Workbook

Sheet RESUMEN. TXT
B1: =+[1]LISTADOS!A4 -> SEMANA DEL 08/12/2025 AL 14/12/2025
B2: NOMBRE | C2: CI | D2: F.INGRESO | E2: CARGO | F2: EMPRESA | G2: POSEE CUENTA PROVINCIAL | H2: BANCO | I2: N° CUENTA | J2: TIPO | K2: NOMINA FISCAL BS | L2: CUMPLIMIENTO DEL BENEFICIO DE ALIMENTACION DE LOS TRABAJADORES. ART 105 | M2: OBSERVACIONES | N2: SUMA | O2: PAGO $ | P2: SEMANAL$
B3: YEREHIMA CARDENAS JAIME | C3: 15906403 | D3: 45362 | E3: COORD. ADMINISTRATIVO | F3: FARMACIA LOS YANEZ DE OSPINO, C.A | G3: SI | H3: BANCO PROVINCIAL | I3: 0108-0542-28-0100124898 | J3: AHORRO | K3: =VLOOKUP(C3,'CALCULO BS'!$C$7:AT$95,44,0) -> 4609.9167 | L3: =VLOOKUP(C3,'CALCULO BONO '!$B$8:P$122,12,0) -> 65626.6 | N3: =+K3+L3 -> 70236.517 | O3: =+N3/LISTADOS!Q$5 -> 218.7849 | P3: =VLOOKUP(C3,LISTADOS!$C$7:Q$19,11,0) -> 220
B4: ADRIANA MORENO MARQUEZ | C4: 30329814 | D4: 45136 | E4: CAJERO (A) | F4: FARMACIA LOS YANEZ DE OSPINO, C.A | G4: SI | H4: BANCO PROVINCIAL | I4: 0108-0201-65-0100281905 | J4: CORRIENTE | K4: =VLOOKUP(C4,'CALCULO BS'!C8:AT96,44,0) -> 3047.3033 | L4: =VLOOKUP(C4,'CALCULO BONO '!$B$8:P$122,12,0) -> 35723.6 | N4: =+K4+L4 -> 38770.903 | O4: =+N4/LISTADOS!Q$5 -> 120.77034 | P4: =VLOOKUP(C4,LISTADOS!$C$7:Q$19,11,0) -> 120
B5: MATERAN CUMANA SKARLETH | C5: 31272373 | D5: 44998 | E5: AUX. DE ALMACEN | F5: FARMACIA LOS YANEZ DE OSPINO, C.A | G5: SI | H5: BANCO PROVINCIAL | I5: 0108-0201-65-0100278289 | J5: CORRIENTE | K5: =VLOOKUP(C5,'CALCULO BS'!$C$7:AT$95,44,0) -> 3171.6 | L5: =VLOOKUP(C5,'CALCULO BONO '!$B$8:P$122,12,0) -> 29303 | N5: =+K5+L5 -> 32474.6 | O5: =+N5/LISTADOS!Q$5 -> 101.15752 | P5: =VLOOKUP(C5,LISTADOS!$C$7:Q$19,11,0) -> 100
B6: VALLADARES MEDINA EMILIO JOSE | C6: 12647713 | D6: 45079 | E6: SUPERVISOR DE VENTAS | F6: FARMACIA LOS YANEZ DE OSPINO, C.A | G6: SI | H6: BANCO PROVINCIAL | I6: 0108-2422-26-0100104904 | J6: CORRIENTE | K6: =VLOOKUP(C6,'CALCULO BS'!$C$7:AT$95,44,0) -> 3953.25 | L6: =VLOOKUP(C6,'CALCULO BONO '!$B$8:P$122,12,0) -> 40944.2 | N6: =+K6+L6 -> 44897.45 | O6: =+N6/LISTADOS!Q$5 -> 139.85437 | P6: =VLOOKUP(C6,LISTADOS!$C$7:Q$19,11,0) -> 140
B7: PEREZ GORDILLO JEFERSSON ALEXANDER | C7: 28427378 | D7: 45708 | E7: SUPERVISOR DE ALMACEN | F7: FARMACIA LOS YANEZ DE OSPINO, C.A | G7: SI | H7: BANCO PROVINCIAL | I7: 0108-2422-27-0100074746 | J7: CORRIENTE | K7: =VLOOKUP(C7,'CALCULO BS'!$C$7:AT$95,44,0) -> 3608.226 | L7: =VLOOKUP(C7,'CALCULO BONO '!$B$8:P$122,12,0) -> 40944.2 | N7: =+K7+L7 -> 44552.426 | O7: =+N7/LISTADOS!Q$5 -> 138.77963 | P7: =VLOOKUP(C7,LISTADOS!$C$7:Q$19,11,0) -> 140
B8: MOISES SEBASTIAN YANEZ FERRER | C8: 26940897 | D8: 45712 | E8: GERENTE | F8: FARMACIA LOS YANEZ DE OSPINO, C.A | G8: SI | H8: BANCO PROVINCIAL | I8: 0108-0064-1401-0032-9645 | J8: CORRIENTE | K8: =VLOOKUP(C8,'CALCULO BS'!$C$7:AT$95,44,0) -> 5618.25 | L8: =VLOOKUP(C8,'CALCULO BONO '!$B$8:P$122,12,0) -> 65626.6 | N8: =+K8+L8 -> 71244.85 | O8: =+N8/LISTADOS!Q$5 -> 221.92583 | P8: =VLOOKUP(C8,LISTADOS!$C$7:Q$19,11,0) -> 220
B9: JOSE ADEMIR ALDANA AZUAJE | C9: 18251792 | D9: 45323 | E9: FARMACEUTICO | F9: FARMACIA LOS YANEZ DE OSPINO, C.A | G9: SI | H9: BANCO PROVINCIAL | I9: 0108-0111-7001-0005-2133 | J9: CORRIENTE | K9: =VLOOKUP(C9,'CALCULO BS'!$C$7:AT$95,44,0) -> 39720.713 | L9: 0 | N9: =+K9+L9 -> 39720.713 | O9: =+N9/LISTADOS!Q$5 -> 123.72897 | P9: =VLOOKUP(C9,LISTADOS!$C$7:Q$19,11,0) -> 250
B10: YENNIFER ALEXANDRA ESPINOZA BOLIVAR | C10: 30240358 | D10: 45999 | E10: PROMOTOR DE VENTA | F10: FARMACIA LOS YANEZ DE OSPINO, C.A | G10: NO | H10: BANCO VENEZUELA | I10: 0102-0741-0700-0028-4017 | J10: CORRIENTE | K10: =VLOOKUP(C10,'CALCULO BS'!$C$7:AT$95,44,0) -> 2925.9 | L10: =VLOOKUP(C10,'CALCULO BONO '!$B$8:P$122,12,0) -> 22882.4 | N10: =+K10+L10 -> 25808.3 | O10: =+N10/LISTADOS!Q$5 -> 80.392175 | P10: =VLOOKUP(C10,LISTADOS!$C$7:Q$19,11,0) -> 80
J11: TOTAL | K11: =SUM(K3:K10) -> 66655.159 | L11: =SUM(L3:L10) -> 301050.6

Sheet LISTADOS
G2: GRUPO FARMACIAS GFO OSPINO
A4: SEMANA DEL 08/12/2025 AL 14/12/2025
A5: RESUMEN SEMANAL | P5: TASA $ | Q5: 321.03
A6: N° | B6: NOMBRE | C6: CI | D6: F.INGRESO | E6: CARGOS | F6: FARMACIA | G6: EMPRESA | H6: RIF | I6: DIRECCION | J6: BANCO | K6: N° DE CUENTA | L6: TIPO DE CUENTA | M6: SUELDO $ | N6: SUELDO MENSUAL | O6: SUELDO QCNAL | P6: INGRESO SEMANAL BS | Q6: CALCULO PARA BONIFICACION
A7: 1 | B7: YEREHIMA CARDENAS JAIME | C7: 15906403 | D7: 45362 | E7: COORD. ADMINISTRATIVO | F7: FARMACIA LOS YANEZ DE OSPINO, C.A | G7: FARMACIA LOS YANEZ DE OSPINO, C.A | H7: RIF J-500253052 | I7: Carrera 3 esquina calle 10, Barrio curazao | J7: BANCO MERCANTIL | K7: 0105-0059-17-0059291494 | L7: AHORRO | M7: =110*2 -> 220 | N7: =2500*4 -> 10000 | O7: =2500*2 -> 5000 | P7: =M7*$Q$5 -> 70626.6 | Q7: =P7-O7 -> 65626.6 | R7: =+Q7/Q5 -> 204.42513
A8: =A7+1 -> 2 | B8: ADRIANA MORENO MARQUEZ | C8: 30329814 | D8: 45136 | E8: CAJERO (A) | F8: FARMACIA LOS YANEZ DE OSPINO, C.A | G8: FARMACIA LOS YANEZ DE OSPINO, C.A | H8: RIF J-500253052 | I8: Carrera 3 esquina calle 10, Barrio curazao | J8: BANCO VENEZUELA | K8: 0102-0741-0800-0039-1379 | L8: CORRIENTE | M8: =60*2 -> 120 | N8: =1400*4 -> 5600 | O8: =1400*2 -> 2800 | P8: =M8*$Q$5 -> 38523.6 | Q8: =P8-O8 -> 35723.6 | R8: =+O7/Q5 -> 15.574868
A9: =A8+1 -> 3 | B9: MATERAN CUMANA SKARLETH | C9: 31272373 | D9: 44998 | E9: AUX. DE ALMACEN | F9: FARMACIA LOS YANEZ DE OSPINO, C.A | G9: FARMACIA LOS YANEZ DE OSPINO, C.A | H9: RIF J-500253052 | I9: Carrera 3 esquina calle 10, Barrio curazao | J9: BANCO VENEZUELA | K9: 0102-0346-5900-0142-7271 | L9: CORRIENTE | M9: =50*2 -> 100 | N9: =1400*4 -> 5600 | O9: =1400*2 -> 2800 | P9: =M9*$Q$5 -> 32103 | Q9: =P9-O9 -> 29303
A10: =A9+1 -> 4 | B10: YUSMARY MARQUEZ OCANTO | C10: 19031701 | D10: 45474 | E10: AUX. DE ALMACEN | F10: FARMACIA LOS YANEZ DE OSPINO, C.A | G10: FARMACIA LOS YANEZ DE OSPINO, C.A | H10: RIF J-500253052 | I10: Carrera 3 esquina calle 10, Barrio curazao | J10: BANCO VENEZUELA | K10: 0102-0346-54-0001448357 | L10: CORRIENTE | M10: =50*2 -> 100 | N10: =1400*4 -> 5600 | O10: =1400*2 -> 2800 | P10: =M10*$Q$5 -> 32103 | Q10: =P10-O10 -> 29303
A11: =A10+1 -> 5 | B11: VALLADARES MEDINA EMILIO JOSE | C11: 12647713 | D11: 45079 | E11: SUPERVISOR DE VENTAS | F11: FARMACIA LOS YANEZ DE OSPINO, C.A | G11: FARMACIA LOS YANEZ DE OSPINO, C.A | H11: RIF J-500253052 | I11: Carrera 3 esquina calle 10, Barrio curazao | J11: BANCO PROVINCIAL | K11: 0108-2422-26-0100104904 | L11: CORRIENTE | M11: =70*2 -> 140 | N11: =2000*4 -> 8000 | O11: =2000*2 -> 4000 | P11: =M11*$Q$5 -> 44944.2 | Q11: =P11-O11 -> 40944.2
A12: =A11+1 -> 6 | B12: NORALYS AZUAJE CONTRERAS | C12: 13329198 | D12: 45378 | E12: CAJERO (A) | F12: FARMACIA LOS YANEZ DE OSPINO, C.A | G12: FARMACIA LOS YANEZ DE OSPINO, C.A | H12: RIF J-500253052 | I12: Carrera 3 esquina calle 10, Barrio curazao | J12: BANCO BANESCO | K12: 0134-0946-36-0001095169 | L12: CORRIENTE | M12: =60*2 -> 120 | N12: =1400*4 -> 5600 | O12: =1400*2 -> 2800 | P12: =M12*$Q$5 -> 38523.6 | Q12: =P12-O12 -> 35723.6
A13: =A12+1 -> 7 | B13: GARCIAS BASTIDAS BIANCA ROSSELA | C13: 27938750 | D13: 45474 | E13: CAJERO (A) | F13: FARMACIA LOS YANEZ DE OSPINO, C.A | G13: FARMACIA LOS YANEZ DE OSPINO, C.A | H13: RIF J-500253052 | I13: Carrera 3 esquina calle 10, Barrio curazao | J13: BANCO VENEZUELA | K13: 0102-0346-58-0106623807 | L13: AHORRO | M13: =60*2 -> 120 | N13: =1400*4 -> 5600 | O13: =1400*2 -> 2800 | P13: =M13*$Q$5 -> 38523.6 | Q13: =P13-O13 -> 35723.6
A14: =A13+1 -> 8 | B14: HANIREE UGARTE | C14: 25016178 | D14: 45691 | E14: CAJERO (A) | F14: FARMACIA LOS YANEZ DE OSPINO, C.A | G14: FARMACIA LOS YANEZ DE OSPINO, C.A | H14: RIF J-500253052 | I14: Carrera 3 esquina calle 10, Barrio curazao | J14: BANCO BANCAMIGA | K14: 0172-0250-2325-0804-9679 | L14: CORRIENTE | M14: =60*2 -> 120 | N14: =1400*4 -> 5600 | O14: =1400*2 -> 2800 | P14: =M14*$Q$5 -> 38523.6 | Q14: =P14-O14 -> 35723.6
A15: =A14+1 -> 9 | B15: PEREZ GORDILLO JEFERSSON ALEXANDER | C15: 28427378 | D15: 45708 | E15: SUPERVISOR DE ALMACEN | F15: FARMACIA LOS YANEZ DE OSPINO, C.A | G15: FARMACIA LOS YANEZ DE OSPINO, C.A | H15: RIF J-500253052 | I15: Carrera 3 esquina calle 10, Barrio curazao | J15: BANCO VENEZUELA | K15: 0102-0741-0200-0059-4888 | L15: CORRIENTE | M15: =70*2 -> 140 | N15: =2000*4 -> 8000 | O15: =2000*2 -> 4000 | P15: =M15*$Q$5 -> 44944.2 | Q15: =P15-O15 -> 40944.2
A16: =A15+1 -> 10 | B16: LEONARDO ENRRIQUE YANEZ FERRER | C16: 29632132 | D16: 45712 | E16: CAJERO (A) | F16: FARMACIA LOS YANEZ DE OSPINO, C.A | G16: FARMACIA LOS YANEZ DE OSPINO, C.A | H16: RIF J-500253052 | I16: Carrera 3 esquina calle 10, Barrio curazao | J16: BANCO PROVINCIAL | K16: 0108-0064-18-0100331070 | L16: CORRIENTE | M16: =70*2 -> 140 | N16: =1400*4 -> 5600 | O16: =1400*2 -> 2800 | P16: =M16*$Q$5 -> 44944.2 | Q16: =P16-O16 -> 42144.2
A17: =A16+1 -> 11 | B17: MOISES SEBASTIAN YANEZ FERRER | C17: 26940897 | D17: 45712 | E17: GERENTE | F17: FARMACIA LOS YANEZ DE OSPINO, C.A | G17: FARMACIA LOS YANEZ DE OSPINO, C.A | H17: RIF J-500253052 | I17: Carrera 3 esquina calle 10, Barrio curazao | J17: BANCO PROVINCIAL | K17: 0108-0064-1401-0032-9645 | L17: CORRIENTE | M17: =110*2 -> 220 | N17: =2500*4 -> 10000 | O17: =2500*2 -> 5000 | P17: =M17*$Q$5 -> 70626.6 | Q17: =P17-O17 -> 65626.6
A18: =A17+1 -> 12 | B18: JOSE ADEMIR ALDANA AZUAJE | C18: 18251792 | D18: 45323 | E18: FARMACEUTICO | F18: FARMACIA LOS YANEZ DE OSPINO, C.A | G18: FARMACIA LOS YANEZ DE OSPINO, C.A | H18: RIF J-500253052 | I18: Carrera 3 esquina calle 10, Barrio curazao | J18: BANCO PROVINCIAL | K18: 0108-0111-7001-0005-2133 | L18: CORRIENTE | M18: =125*2 -> 250 | N18: =+M18*Q5 -> 80257.5 | O18: =M18*$Q$5 -> 80257.5 | P18: =M18*$Q$5 -> 80257.5 | Q18: =P18-O18 -> 0
A19: =A18+1 -> 13 | B19: YENNIFER ALEXANDRA ESPINOZA BOLIVAR | C19: 30240358 | D19: 45999 | E19: PROMOTOR DE VENTA | F19: FARMACIA LOS YANEZ DE OSPINO, C.A | G19: FARMACIA LOS YANEZ DE OSPINO, C.A | H19: RIF J-500253052 | I19: Carrera 3 esquina calle 10, Barrio curazao | J19: BANCO VENEZUELA | K19: 0102-0741-0700-0028-4017 | L19: CORRIENTE | M19: =40*2 -> 80 | N19: =1400*4 -> 5600 | O19: =1400*2 -> 2800 | P19: =M19*$Q$5 -> 25682.4 | Q19: =P19-O19 -> 22882.4
O21: =2500*2 -> 5000
O22: =+O21/15 -> 333.33333
O24: =+O22*11 -> 3666.6667
O25: =+O22*4 -> 1333.3333

Sheet CALCULO BS
A1: 80
B4: 1 | C4: 1 | D4: =C4+1 -> 2 | E4: =D4+1 -> 3 | F4: =E4+1 -> 4 | G4: =F4+1 -> 5 | H4: =G4+1 -> 6 | I4: =H4+1 -> 7 | J4: =I4+1 -> 8 | K4: =J4+1 -> 9 | ... BB4: =BA4+1 -> 52
A5: DATOS DEL EMPLEADO | L5: SALARIO INTEGRAL | Q5: ASIGNACIONES | AI5: DEDUCCIONES | AT5: TOTAL | AV5: OBSERVACIONES. | AW5: FARMACIA | AX5: PAGO BONO | AY5: PAGO BONO
A6: N° | B6: NOMBRE | C6: CI | D6: F.INGRESO | E6: CARGO | F6: EMPRESA | G6: RIF | H6: DIRECCION | I6: BANCO | J6: N° CUENTA | K6: TIPO | L6: SALARIO INTEGRAL BS | M6: SALARIO MENSUAL BS | N6: SALARIO DIARIO | O6: HORAS | P6: REPOSO 33,33% | Q6: N | R6: DIAS LABORADOS | S6: N° | T6: DIAS DE DESCANSO | U6: N° | V6: DIAS DE DESCANSO / FERIADOS LABORADOS | W6: N° | X6: REPOSO 100% | Y6: N° | Z6: REPOSO 33,33% | AA6: TRANSPORTE | AB6: N° | AC6: HORAS EXTRAS DIURNA | AD6: N° | AE6: BONO NOTURNO | AF6: PAGO EXTRAS | AG6: BONIFICACION DEL MES | AH6: TOTAL ASIGNACION | AI6: N° LUNES | AJ6: IVSS | AK6: RPE | AL6: INCE | AM6: FAOV | AN6: N | AO6: PERMISO NO REMUNERADO | AP6: N° | AQ6: FALTA INJUSTIFICADA | AR6: RETARDO | AS6: TOTAL DEDUCIONES | AT6: NETO PAGAR EN BS. | AU6: NETO PAGAR EN $ | AV6: OBSERVACIONES | AW6: FARMACIA | AX6: DIAS PAGADO | AY6: DIAS AUSENCIA
A7: 1 | B7: YEREHIMA CARDENAS JAIME | C7: 15906403 | D7: 45362 | E7: =VLOOKUP(C7,[1]LISTADOS!$C$7:$E$210,3,0) -> COORD. ADMINISTRATIVO | F7: FARMACIA LOS YANEZ DE OSPINO, C.A | G7: RIF J-500253052 | H7: Carrera 3 esquina calle 10, Barrio curazao | I7: BANCO MERCANTIL | J7: 0105-0059-17-0059291494 | K7: AHORRO | M7: =VLOOKUP(C7,LISTADOS!$C$7:$O$111,12,0) -> 10000 | N7: =+M7/30 -> 333.33333 | O7: =+N7/7.5 -> 44.444444 | P7: =+N7*0.3333 -> 111.1 | Q7: 11 | R7: =+N7*Q7 -> 3666.6667 | S7: 4 | T7: =(R7+V7+X7+Z7+AC7+AE7+AF7)/11*S7 -> 1333.3333 | U7: 0 | V7: =+U7*N7*1.5 -> 0 | W7: 0 | X7: =+W7*N7 -> 0 | Y7: 0 | Z7: =Y7*P7 -> 0 | AB7: 0 | AC7: =+O7*AB7*1.5 -> 0 | AD7: 0 | AE7: =(O7*AD7)*30% -> 0 | AF7: 0 | AG7: 0 | AH7: =+R7+T7+Z7+AA7+AC7+AG7+AF7+V7+AE7+X7 -> 5000 | AI7: 1 | AJ7: =(((650*12/52)*4%)*AI7) -> 6 | AK7: =(((650*12/52)*0.5%)*AI7) -> 0.75 | AM7: =AH7*1% -> 50 | AN7: 1 | AO7: =AN7*N7 -> 333.33333 | AP7: 0 | AQ7: =+AP7*$N7 -> 0 | AS7: =+AJ7+AM7+AK7+AO7+AQ7+AR7 -> 390.08333 | AT7: =+AH7-AS7 -> 4609.9167 | AV7: 1/2 DIA DE PERMISO 09/12/25 ACTIVIDAD ESCOLAR DE LA HIJA | AW7: FARMACIA LOS YANEZ DE OSPINO, C.A | AZ7: =VLOOKUP(C7,[2]ACTIVOS!$C$7:$H$140,3,0) -> COORD. ADMINISTRATIVO
A8: =+A7+1 -> 2 | B8: ADRIANA MORENO MARQUEZ | C8: 30329814 | D8: 45136 | E8: =VLOOKUP(C8,[1]LISTADOS!$C$7:$E$210,3,0) -> CAJERO (A) | F8: FARMACIA LOS YANEZ DE OSPINO, C.A | G8: RIF J-500253052 | H8: Carrera 3 esquina calle 10, Barrio curazao | I8: BANCO VENEZUELA | J8: 0102-0741-0800-0039-1379 | K8: CORRIENTE | M8: =VLOOKUP(C8,LISTADOS!$C$7:$O$111,12,0) -> 5600 | N8: =+M8/30 -> 186.66667 | O8: =+N8/7.5 -> 24.888889 | P8: =+N8*0.3333 -> 62.216 | Q8: 10 | R8: =+N8*Q8 -> 1866.6667 | S8: 4 | T8: =(R8+V8+X8+Z8+AC8+AE8+AF8)/11*S8 -> 872.92121 | U8: 1 | V8: =+U8*N8*1.5 -> 280 | W8: 1 | X8: =+W8*N8 -> 186.66667 | Y8: 0 | Z8: =Y8*P8 -> 0 | AB8: 0 | AC8: =+O8*AB8*1.5 -> 0 | AD8: 9 | AE8: =(O8*AD8)*30% -> 67.2 | AF8: 0 | AG8: 0 | AH8: =+R8+T8+Z8+AA8+AC8+AG8+AF8+V8+AE8+X8 -> 3273.4545 | AI8: 1 | AJ8: =(((650*12/52)*4%)*AI8) -> 6 | AK8: =(((650*12/52)*0.5%)*AI8) -> 0.75 | AM8: =AH8*1% -> 32.734545 | AN8: 0 | AO8: =AN8*N8 -> 0 | AP8: 1 | AQ8: =+AP8*$N8 -> 186.66667 | AS8: =+AJ8+AM8+AK8+AO8+AQ8+AR8 -> 226.15121 | AT8: =+AH8-AS8 -> 3047.3033 | AV8: FALTA INJUSTIFICADA 08/12/25 Y REPOSO 11/12/25 | AW8: FARMACIA LOS YANEZ DE OSPINO, C.A | AZ8: =VLOOKUP(C8,[2]ACTIVOS!$C$7:$H$140,3,0) -> AUX. DE ALMACEN
A9: =+A8+1 -> 3 | B9: MATERAN CUMANA SKARLETH | C9: 31272373 | D9: 44998 | E9: =VLOOKUP(C9,[1]LISTADOS!$C$7:$E$210,3,0) -> AUX. DE ALMACEN | F9: FARMACIA LOS YANEZ DE OSPINO, C.A | G9: RIF J-500253052 | H9: Carrera 3 esquina calle 10, Barrio curazao | I9: BANCO VENEZUELA | J9: 0102-0346-5900-0142-7271 | K9: CORRIENTE | M9: =VLOOKUP(C9,LISTADOS!$C$7:$O$111,12,0) -> 5600 | N9: =+M9/30 -> 186.66667 | O9: =+N9/8 -> 23.333333 | P9: =+N9*0.3333 -> 62.216 | Q9: 11 | R9: =+N9*Q9 -> 2053.3333 | S9: 4 | T9: =(R9+V9+X9+Z9+AC9+AE9+AF9)/11*S9 -> 856.12121 | U9: 1 | V9: =+U9*N9*1.5 -> 280 | W9: 0 | X9: =+W9*N9 -> 0 | Y9: 0 | Z9: =Y9*P9 -> 0 | AB9: 0 | AC9: =+O9*AB9*1.5 -> 0 | AD9: 3 | AE9: =(O9*AD9)*30% -> 21 | AF9: 0 | AG9: 0 | AH9: =+R9+T9+Z9+AA9+AC9+AG9+AF9+V9+AE9+X9 -> 3210.4545 | AI9: 1 | AJ9: =(((650*12/52)*4%)*AI9) -> 6 | AK9: =(((650*12/52)*0.5%)*AI9) -> 0.75 | AM9: =AH9*1% -> 32.104545 | AN9: 0 | AO9: =AN9*N9 -> 0 | AP9: 0 | AQ9: =+AP9*$N9 -> 0 | AS9: =+AJ9+AM9+AK9+AO9+AQ9+AR9 -> 38.854545 | AT9: =+AH9-AS9 -> 3171.6 | AW9: FARMACIA LOS YANEZ DE OSPINO, C.A | AZ9: =VLOOKUP(C9,[2]ACTIVOS!$C$7:$H$140,3,0) -> AUX. DE ALMACEN
A10: =+A9+1 -> 4 | B10: VALLADARES MEDINA EMILIO JOSE | C10: 12647713 | D10: 45079 | E10: =VLOOKUP(C10,[1]LISTADOS!$C$7:$E$210,3,0) -> SUPERVISOR DE VENTAS | F10: FARMACIA LOS YANEZ DE OSPINO, C.A | G10: RIF J-500253052 | H10: Carrera 3 esquina calle 10, Barrio curazao | I10: BANCO PROVINCIAL | J10: 0108-2422-26-0100104904 | K10: CORRIENTE | M10: =VLOOKUP(C10,LISTADOS!$C$7:$O$111,12,0) -> 8000 | N10: =+M10/30 -> 266.66667 | O10: =+N10/8 -> 33.333333 | P10: =+N10*0.3333 -> 88.88 | Q10: 11 | R10: =+N10*Q10 -> 2933.3333 | S10: 4 | T10: =(R10+V10+X10+Z10+AC10+AE10+AF10)/11*S10 -> 1066.6667 | U10: 0 | V10: =+U10*N10*1.5 -> 0 | W10: 0 | X10: =+W10*N10 -> 0 | Y10: 0 | Z10: =Y10*P10 -> 0 | AB10: 0 | AC10: =+O10*AB10*1.5 -> 0 | AD10: 0 | AE10: =(O10*AD10)*30% -> 0 | AF10: 0 | AG10: 0 | AH10: =+R10+T10+Z10+AA10+AC10+AG10+AF10+V10+AE10+X10 -> 4000 | AI10: 1 | AJ10: =(((650*12/52)*4%)*AI10) -> 6 | AK10: =(((650*12/52)*0.5%)*AI10) -> 0.75 | AM10: =AH10*1% -> 40 | AN10: 0 | AO10: =AN10*N10 -> 0 | AP10: 0 | AQ10: =+AP10*$N10 -> 0 | AS10: =+AJ10+AM10+AK10+AO10+AQ10+AR10 -> 46.75 | AT10: =+AH10-AS10 -> 3953.25 | AW10: FARMACIA LOS YANEZ DE OSPINO, C.A | AZ10: =VLOOKUP(C10,[2]ACTIVOS!$C$7:$H$140,3,0) -> SUPERVISOR DE VENTAS
A11: =+A10+1 -> 5 | B11: PEREZ GORDILLO JEFERSSON ALEXANDER | C11: 28427378 | D11: 45708 | E11: =VLOOKUP(C11,[1]LISTADOS!$C$7:$E$210,3,0) -> SUPERVISOR DE ALMACEN | F11: FARMACIA LOS YANEZ DE OSPINO, C.A | G11: RIF J-500253052 | H11: Carrera 3 esquina calle 10, Barrio curazao | I11: BANCO VENEZUELA | J11: 0102-0741-0200-0059-4888 | K11: CORRIENTE | M11: =VLOOKUP(C11,LISTADOS!$C$7:$O$111,12,0) -> 8000 | N11: =+M11/30 -> 266.66667 | O11: =+N11/8 -> 33.333333 | P11: =+N11*0.3333 -> 88.88 | Q11: 9 | R11: =+N11*Q11 -> 2400 | S11: 4 | T11: =(R11+V11+X11+Z11+AC11+AE11+AF11)/11*S11 -> 973.73091 | U11: 0 | V11: =+U11*N11*1.5 -> 0 | W11: 0 | X11: =+W11*N11 -> 0 | Y11: 2 | Z11: =Y11*P11 -> 177.76 | AB11: 2 | AC11: =+O11*AB11*1.5 -> 100 | AD11: 0 | AE11: =(O11*AD11)*30% -> 0 | AF11: 0 | AG11: 0 | AH11: =+R11+T11+Z11+AA11+AC11+AG11+AF11+V11+AE11+X11 -> 3651.4909 | AI11: 1 | AJ11: =(((650*12/52)*4%)*AI11) -> 6 | AK11: =(((650*12/52)*0.5%)*AI11) -> 0.75 | AM11: =AH11*1% -> 36.514909 | AN11: 0 | AO11: =AN11*N11 -> 0 | AP11: 0 | AQ11: =+AP11*$N11 -> 0 | AS11: =+AJ11+AM11+AK11+AO11+AQ11+AR11 -> 43.264909 | AT11: =+AH11-AS11 -> 3608.226 | AW11: FARMACIA LOS YANEZ DE OSPINO, C.A | AZ11: =VLOOKUP(C11,[2]ACTIVOS!$C$7:$H$140,3,0) -> SUPERVISOR DE ALMACEN
A12: =+A11+1 -> 6 | B12: MOISES SEBASTIAN YANEZ FERRER | C12: 26940897 | D12: 45712 | E12: =VLOOKUP(C12,[1]LISTADOS!$C$7:$E$210,3,0) -> GERENTE | F12: FARMACIA LOS YANEZ DE OSPINO, C.A | G12: RIF J-500253052 | H12: Carrera 3 esquina calle 10, Barrio curazao | I12: BANCO PROVINCIAL | J12: 0108-0064-1401-0032-9645 | K12: CORRIENTE | M12: =VLOOKUP(C12,LISTADOS!$C$7:$O$111,12,0) -> 10000 | N12: =+M12/30 -> 333.33333 | O12: =+N12/7.5 -> 44.444444 | P12: =+N12*0.3333 -> 111.1 | Q12: 11 | R12: =+N12*Q12 -> 3666.6667 | S12: 4 | T12: =(R12+V12+X12+Z12+AC12+AE12+AF12)/11*S12 -> 1515.1515 | U12: 1 | V12: =+U12*N12*1.5 -> 500 | W12: 0 | X12: =+W12*N12 -> 0 | Y12: 0 | Z12: =Y12*P12 -> 0 | AB12: 0 | AC12: =+O12*AB12*1.5 -> 0 | AD12: 0 | AE12: =(O12*AD12)*30% -> 0 | AF12: 0 | AG12: 0 | AH12: =+R12+T12+Z12+AA12+AC12+AG12+AF12+V12+AE12+X12 -> 5681.8182 | AI12: 1 | AJ12: =(((650*12/52)*4%)*AI12) -> 6 | AK12: =(((650*12/52)*0.5%)*AI12) -> 0.75 | AM12: =AH12*1% -> 56.818182 | AN12: 0 | AO12: =AN12*N12 -> 0 | AP12: 0 | AQ12: =+AP12*$N12 -> 0 | AS12: =+AJ12+AM12+AK12+AO12+AQ12+AR12 -> 63.568182 | AT12: =+AH12-AS12 -> 5618.25 | AW12: FARMACIA LOS YANEZ DE OSPINO, C.A | AZ12: =VLOOKUP(C12,[2]ACTIVOS!$C$7:$H$140,3,0) -> GERENTE
A13: =+A12+1 -> 7 | B13: JOSE ADEMIR ALDANA AZUAJE | C13: 18251792 | D13: 45323 | E13: FARMACEUTICO | F13: FARMACIA LOS YANEZ DE OSPINO, C.A | G13: RIF J-500253052 | H13: Carrera 3 esquina calle 10, Barrio curazao | I13: BANCO PROVINCIAL | J13: 0108-0111-7001-0005-2133 | K13: CORRIENTE | M13: =VLOOKUP(C13,LISTADOS!$C$7:$O$111,12,0) -> 80257.5 | N13: =+M13/30 -> 2675.25 | O13: =+N13/8 -> 334.40625 | P13: =+N13*0.3333 -> 891.66082 | Q13: 11 | R13: =+N13*Q13 -> 29427.75 | S13: 4 | T13: =(R13+V13+X13+Z13+AC13+AE13+AF13)/11*S13 -> 10701 | U13: 0 | V13: =+U13*N13*1.5 -> 0 | W13: 0 | X13: =+W13*N13 -> 0 | Y13: 0 | Z13: =Y13*P13 -> 0 | AB13: 0 | AC13: =+O13*AB13*1.5 -> 0 | AD13: 0 | AE13: =(O13*AD13)*30% -> 0 | AF13: 0 | AG13: 0 | AH13: =+R13+T13+Z13+AA13+AC13+AG13+AF13+V13+AE13+X13 -> 40128.75 | AI13: 1 | AJ13: =(((650*12/52)*4%)*AI13) -> 6 | AK13: =(((650*12/52)*0.5%)*AI13) -> 0.75 | AM13: =AH13*1% -> 401.2875 | AN13: 0 | AO13: =AN13*N13 -> 0 | AP13: 0 | AQ13: =+AP13*$N13 -> 0 | AS13: =+AJ13+AM13+AK13+AO13+AQ13+AR13 -> 408.0375 | AT13: =+AH13-AS13 -> 39720.713 | AW13: FARMACIA LOS YANEZ DE OSPINO, C.A | AZ13: =VLOOKUP(C13,[2]ACTIVOS!$C$7:$H$140,3,0) -> FARMACEUTICO
A14: =+A13+1 -> 8 | B14: YENNIFER ALEXANDRA ESPINOZA BOLIVAR | C14: 30240358 | D14: 45999 | E14: PROMOTOR DE VENTA | F14: FARMACIA LOS YANEZ DE OSPINO, C.A | G14: RIF J-500253052 | H14: Carrera 3 esquina calle 10, Barrio curazao | I14: BANCO VENEZUELA | J14: 0102-0741-0700-0028-4017 | K14: CORRIENTE | M14: =VLOOKUP(C14,LISTADOS!$C$7:$O$111,12,0) -> 5600 | N14: =+M14/30 -> 186.66667 | O14: =+N14/8 -> 23.333333 | P14: =+N14*0.3333 -> 62.216 | Q14: 11 | R14: =+N14*Q14 -> 2053.3333 | S14: 4 | T14: =(R14+V14+X14+Z14+AC14+AE14+AF14)/11*S14 -> 789.93939 | U14: 0 | V14: =+U14*N14*1.5 -> 0 | W14: 0 | X14: =+W14*N14 -> 0 | Y14: 0 | Z14: =Y14*P14 -> 0 | AB14: 3 | AC14: =+O14*AB14*1.5 -> 105 | AD14: 2 | AE14: =(O14*AD14)*30% -> 14 | AF14: 0 | AG14: 0 | AH14: =+R14+T14+Z14+AA14+AC14+AG14+AF14+V14+AE14+X14 -> 2962.2727 | AI14: 1 | AJ14: =(((650*12/52)*4%)*AI14) -> 6 | AK14: =(((650*12/52)*0.5%)*AI14) -> 0.75 | AM14: =AH14*1% -> 29.622727 | AN14: 0 | AO14: =AN14*N14 -> 0 | AP14: 0 | AQ14: =+AP14*$N14 -> 0 | AS14: =+AJ14+AM14+AK14+AO14+AQ14+AR14 -> 36.372727 | AT14: =+AH14-AS14 -> 2925.9 | AW14: FARMACIA LOS YANEZ DE OSPINO, C.A | AZ14: =VLOOKUP(C14,[2]ACTIVOS!$C$7:$H$140,3,0) -> PROMOTOR DE VENTA
R16: =SUM(R7:R15) -> 48067.75 | T16: =SUM(T7:T15) -> 18108.864 | V16: =SUM(V7:V15) -> 1060 | Z16: =SUM(Z7:Z15) -> 177.76 | AC16: =SUM(AC7:AC15) -> 205 | AE16: =SUM(AE7:AE15) -> 102.2 | AF16: =SUM(AF7:AF15) -> 0 | AH16: =SUM(AH7:AH15) -> 67908.241 | AJ16: =SUM(AJ7:AJ15) -> 48 | AK16: =SUM(AK7:AK15) -> 6 | AO16: =SUM(AO7:AO15) -> 333.33333 | AQ16: =SUM(AQ7:AQ15) -> 186.66667 | AS16: =SUM(AS7:AS15) -> 1253.0824 | AT16: =SUM(AT7:AT15) -> 66655.159 | AU16: =SUM(AU7:AU15) -> 0
AS18: TOTAL BS. | AT18: =+AT16 -> 66655.159
AS19: TOTAL $ | AT19: =+AT18/[1]LISTADOS!P5 -> 248.9455

Sheet CALCULO BONO 
A1: RECIBOS DE PAGO (BONO DE CUMPLIMIENTO DEL BENEFICIO DE ALIMENTACION PARA LOS TRABAJADORES Y LAS TRABAJADORAS ARTICULO 105. LITERAL N°2 DE LA LEY ORGANIGA DEL TRABAJO LOS TRABAJADORES Y LAS TRABAJADORAS LOTT) | R1: 10
B2: FARMACIA: | C2: FARMACIA SANTA CRUZ DE OSPINO C.A
B3: RIF: | C3: =+IFERROR(VLOOKUP(C2,[1]DATOS!$C$2:$E$9,2,0)," ") -> J-500304773
B4: DIRECCION: | C4: =+IFERROR(VLOOKUP(C2,[1]DATOS!$C$2:$E$9,3,0)," ") -> AV. LIBERTADOR ENTRE CALLE CEDEÑO Y NEGRO PRIMERO LOCAL NRO 3- MUNICIPIO OSPINO PORTUGUESA
B5: PERIODO: | C5: =+[1]LISTADOS!$A$4 -> SEMANA DEL 08/12/2025 AL 14/12/2025
A7: NOMBRE Y APELLIDOS | B7: C.I | C7: FECHA DE INGRESO | D7: CARGO | E7: BANCO | F7: N° CUENTA | G7: TIPO | H7: EMPRESA | I7: BONO ASIGNADO | J7: PAGO EXTRA | K7: BONIFICACION | L7: DEDUCIONES | M7: MONTO NETO A PAGAR Bs. | N7: OBSERVACIONES | O7: FIRMA | P7: HUELLAS | Q7: MONTO $ | R7: 241.58
A8: YEREHIMA CARDENAS JAIME | B8: =+IFERROR(VLOOKUP($A8,'[1]CALCULO BS'!$B$6:$AV$1171,2,0)," ") -> 15906403 | C8: =+IFERROR(VLOOKUP($A8,'[1]CALCULO BS'!$B$6:$AV$1171,3,0)," ") -> 45362 | D8: =+IFERROR(VLOOKUP($A8,'[1]CALCULO BS'!$B$6:$AV$1171,4,0)," ") -> COORD. ADMINISTRATIVO | E8: =+IFERROR(VLOOKUP($A8,'[1]CALCULO BS'!$B$6:$AV$1171,8,0)," ") -> BANCO MERCANTIL | F8: =+IFERROR(VLOOKUP($A8,'[1]CALCULO BS'!$B$6:$AV$1171,9,0)," ") -> 0105-0059-17-0059291494 | G8: =+IFERROR(VLOOKUP($A8,'[1]CALCULO BS'!$B$6:$AV$1171,10,0)," ") -> AHORRO | H8: =+IFERROR(VLOOKUP($A8,'[1]CALCULO BS'!$B$6:$AV$1171,5,0)," ") -> FARMACIA LOS YANEZ DE OSPINO, C.A | I8: =VLOOKUP(B8,LISTADOS!$C$7:Q$19,15,0) -> 65626.6 | J8: =(VLOOKUP(B8,'[1]CALCULO BS'!$C$7:$U$95,19,0)*($R$1*[1]LISTADOS!$P$5))-VLOOKUP(B8,'[1]CALCULO BS'!$C$7:$V$95,20,0) -> 0 | M8: =(I8+J8)-L8 -> 65626.6 | Q8: =+L8/R$7 -> 0
A9: ADRIANA MORENO MARQUEZ | B9: =+IFERROR(VLOOKUP($A9,'[1]CALCULO BS'!$B$6:$AV$1171,2,0)," ") -> 30329814 | C9: =+IFERROR(VLOOKUP($A9,'[1]CALCULO BS'!$B$6:$AV$1171,3,0)," ") -> 45136 | D9: =+IFERROR(VLOOKUP($A9,'[1]CALCULO BS'!$B$6:$AV$1171,4,0)," ") -> CAJERO (A) | E9: =+IFERROR(VLOOKUP($A9,'[1]CALCULO BS'!$B$6:$AV$1171,8,0)," ") -> BANCO VENEZUELA | F9: =+IFERROR(VLOOKUP($A9,'[1]CALCULO BS'!$B$6:$AV$1171,9,0)," ") -> 0102-0741-0800-0039-1379 | G9: =+IFERROR(VLOOKUP($A9,'[1]CALCULO BS'!$B$6:$AV$1171,10,0)," ") -> CORRIENTE | H9: =+IFERROR(VLOOKUP($A9,'[1]CALCULO BS'!$B$6:$AV$1171,5,0)," ") -> FARMACIA LOS YANEZ DE OSPINO, C.A | I9: =VLOOKUP(B9,LISTADOS!$C$7:Q$19,15,0) -> 35723.6 | J9: =(VLOOKUP(B9,'[1]CALCULO BS'!$C$7:$U$95,19,0)*($R$1*[1]LISTADOS!$P$5))-VLOOKUP(B9,'[1]CALCULO BS'!$C$7:$V$95,20,0) -> 0 | M9: =(I9+J9)-L9 -> 35723.6 | Q9: =+L9/R$7 -> 0
A10: MATERAN CUMANA SKARLETH | B10: =+IFERROR(VLOOKUP($A10,'[1]CALCULO BS'!$B$6:$AV$1171,2,0)," ") -> 31272373 | C10: =+IFERROR(VLOOKUP($A10,'[1]CALCULO BS'!$B$6:$AV$1171,3,0)," ") -> 44998 | D10: =+IFERROR(VLOOKUP($A10,'[1]CALCULO BS'!$B$6:$AV$1171,4,0)," ") -> AUX. DE ALMACEN | E10: =+IFERROR(VLOOKUP($A10,'[1]CALCULO BS'!$B$6:$AV$1171,8,0)," ") -> BANCO VENEZUELA | F10: =+IFERROR(VLOOKUP($A10,'[1]CALCULO BS'!$B$6:$AV$1171,9,0)," ") -> 0102-0346-5900-0142-7271 | G10: =+IFERROR(VLOOKUP($A10,'[1]CALCULO BS'!$B$6:$AV$1171,10,0)," ") -> CORRIENTE | H10: =+IFERROR(VLOOKUP($A10,'[1]CALCULO BS'!$B$6:$AV$1171,5,0)," ") -> FARMACIA LOS YANEZ DE OSPINO, C.A | I10: =VLOOKUP(B10,LISTADOS!$C$7:Q$19,15,0) -> 29303 | J10: =(VLOOKUP(B10,'[1]CALCULO BS'!$C$7:$U$95,19,0)*($R$1*[1]LISTADOS!$P$5))-VLOOKUP(B10,'[1]CALCULO BS'!$C$7:$V$95,20,0) -> 0 | M10: =(I10+J10)-L10 -> 29303 | Q10: =+L10/R$7 -> 0
A11: YUSMARY MARQUEZ OCANTO | B11: =+IFERROR(VLOOKUP($A11,'[1]CALCULO BS'!$B$6:$AV$1171,2,0)," ") -> 19031701 | C11: =+IFERROR(VLOOKUP($A11,'[1]CALCULO BS'!$B$6:$AV$1171,3,0)," ") -> 45474 | D11: =+IFERROR(VLOOKUP($A11,'[1]CALCULO BS'!$B$6:$AV$1171,4,0)," ") -> AUX. DE ALMACEN | E11: =+IFERROR(VLOOKUP($A11,'[1]CALCULO BS'!$B$6:$AV$1171,8,0)," ") -> BANCO VENEZUELA | F11: =+IFERROR(VLOOKUP($A11,'[1]CALCULO BS'!$B$6:$AV$1171,9,0)," ") -> 0102-0346-54-0001448357 | G11: =+IFERROR(VLOOKUP($A11,'[1]CALCULO BS'!$B$6:$AV$1171,10,0)," ") -> CORRIENTE | H11: =+IFERROR(VLOOKUP($A11,'[1]CALCULO BS'!$B$6:$AV$1171,5,0)," ") -> FARMACIA LOS YANEZ DE OSPINO, C.A | I11: =VLOOKUP(B11,LISTADOS!$C$7:Q$19,15,0) -> 29303 | J11: =(VLOOKUP(B11,'[1]CALCULO BS'!$C$7:$U$95,19,0)*($R$1*[1]LISTADOS!$P$5))-VLOOKUP(B11,'[1]CALCULO BS'!$C$7:$V$95,20,0) -> 0 | M11: =(I11+J11)-L11 -> 29303 | Q11: =+L11/R$7 -> 0
A12: VALLADARES MEDINA EMILIO JOSE | B12: =+IFERROR(VLOOKUP($A12,'[1]CALCULO BS'!$B$6:$AV$1171,2,0)," ") -> 12647713 | C12: =+IFERROR(VLOOKUP($A12,'[1]CALCULO BS'!$B$6:$AV$1171,3,0)," ") -> 45079 | D12: =+IFERROR(VLOOKUP($A12,'[1]CALCULO BS'!$B$6:$AV$1171,4,0)," ") -> SUPERVISOR DE VENTAS | E12: =+IFERROR(VLOOKUP($A12,'[1]CALCULO BS'!$B$6:$AV$1171,8,0)," ") -> BANCO PROVINCIAL | F12: =+IFERROR(VLOOKUP($A12,'[1]CALCULO BS'!$B$6:$AV$1171,9,0)," ") -> 0108-2422-26-0100104904 | G12: =+IFERROR(VLOOKUP($A12,'[1]CALCULO BS'!$B$6:$AV$1171,10,0)," ") -> CORRIENTE | H12: =+IFERROR(VLOOKUP($A12,'[1]CALCULO BS'!$B$6:$AV$1171,5,0)," ") -> FARMACIA LOS YANEZ DE OSPINO, C.A | I12: =VLOOKUP(B12,LISTADOS!$C$7:Q$19,15,0) -> 40944.2 | J12: =(VLOOKUP(B12,'[1]CALCULO BS'!$C$7:$U$95,19,0)*($R$1*[1]LISTADOS!$P$5))-VLOOKUP(B12,'[1]CALCULO BS'!$C$7:$V$95,20,0) -> 0 | M12: =(I12+J12)-L12 -> 40944.2 | Q12: =+L12/R$7 -> 0
A13: NORALYS AZUAJE CONTRERAS | B13: =+IFERROR(VLOOKUP($A13,'[1]CALCULO BS'!$B$6:$AV$1171,2,0)," ") -> 13329198 | C13: =+IFERROR(VLOOKUP($A13,'[1]CALCULO BS'!$B$6:$AV$1171,3,0)," ") -> 45378 | D13: =+IFERROR(VLOOKUP($A13,'[1]CALCULO BS'!$B$6:$AV$1171,4,0)," ") -> CAJERO (A) | E13: =+IFERROR(VLOOKUP($A13,'[1]CALCULO BS'!$B$6:$AV$1171,8,0)," ") -> BANCO BANESCO | F13: =+IFERROR(VLOOKUP($A13,'[1]CALCULO BS'!$B$6:$AV$1171,9,0)," ") -> 0134-0946-36-0001095169 | G13: =+IFERROR(VLOOKUP($A13,'[1]CALCULO BS'!$B$6:$AV$1171,10,0)," ") -> CORRIENTE | H13: =+IFERROR(VLOOKUP($A13,'[1]CALCULO BS'!$B$6:$AV$1171,5,0)," ") -> FARMACIA LOS YANEZ DE OSPINO, C.A | I13: =VLOOKUP(B13,LISTADOS!$C$7:Q$19,15,0) -> 35723.6 | J13: =(VLOOKUP(B13,'[1]CALCULO BS'!$C$7:$U$95,19,0)*($R$1*[1]LISTADOS!$P$5))-VLOOKUP(B13,'[1]CALCULO BS'!$C$7:$V$95,20,0) -> 2377.5 | M13: =(I13+J13)-L13 -> 38101.1 | Q13: =+L13/R$7 -> 0
A14: GARCIAS BASTIDAS BIANCA ROSSELA | B14: =+IFERROR(VLOOKUP($A14,'[1]CALCULO BS'!$B$6:$AV$1171,2,0)," ") -> 27938750 | C14: =+IFERROR(VLOOKUP($A14,'[1]CALCULO BS'!$B$6:$AV$1171,3,0)," ") -> 45474 | D14: =+IFERROR(VLOOKUP($A14,'[1]CALCULO BS'!$B$6:$AV$1171,4,0)," ") -> CAJERO (A) | E14: =+IFERROR(VLOOKUP($A14,'[1]CALCULO BS'!$B$6:$AV$1171,8,0)," ") -> BANCO VENEZUELA | F14: =+IFERROR(VLOOKUP($A14,'[1]CALCULO BS'!$B$6:$AV$1171,9,0)," ") -> 0102-0346-58-0106623807 | G14: =+IFERROR(VLOOKUP($A14,'[1]CALCULO BS'!$B$6:$AV$1171,10,0)," ") -> AHORRO | H14: =+IFERROR(VLOOKUP($A14,'[1]CALCULO BS'!$B$6:$AV$1171,5,0)," ") -> FARMACIA LOS YANEZ DE OSPINO, C.A | I14: =VLOOKUP(B14,LISTADOS!$C$7:Q$19,15,0) -> 35723.6 | J14: =(VLOOKUP(B14,'[1]CALCULO BS'!$C$7:$U$95,19,0)*($R$1*[1]LISTADOS!$P$5))-VLOOKUP(B14,'[1]CALCULO BS'!$C$7:$V$95,20,0) -> 0 | M14: =(I14+J14)-L14 -> 35723.6 | Q14: =+L14/R$7 -> 0
A15: HANIREE UGARTE | B15: =+IFERROR(VLOOKUP($A15,'[1]CALCULO BS'!$B$6:$AV$1171,2,0)," ") -> 25016178 | C15: =+IFERROR(VLOOKUP($A15,'[1]CALCULO BS'!$B$6:$AV$1171,3,0)," ") -> 45691 | D15: =+IFERROR(VLOOKUP($A15,'[1]CALCULO BS'!$B$6:$AV$1171,4,0)," ") -> CAJERO (A) | E15: =+IFERROR(VLOOKUP($A15,'[1]CALCULO BS'!$B$6:$AV$1171,8,0)," ") -> BANCO BANCAMIGA | F15: =+IFERROR(VLOOKUP($A15,'[1]CALCULO BS'!$B$6:$AV$1171,9,0)," ") -> 0172-0250-2325-0804-9679 | G15: =+IFERROR(VLOOKUP($A15,'[1]CALCULO BS'!$B$6:$AV$1171,10,0)," ") -> CORRIENTE | H15: =+IFERROR(VLOOKUP($A15,'[1]CALCULO BS'!$B$6:$AV$1171,5,0)," ") -> FARMACIA LOS YANEZ DE OSPINO, C.A | I15: =VLOOKUP(B15,LISTADOS!$C$7:Q$19,15,0) -> 35723.6 | J15: =(VLOOKUP(B15,'[1]CALCULO BS'!$C$7:$U$95,19,0)*($R$1*[1]LISTADOS!$P$5))-VLOOKUP(B15,'[1]CALCULO BS'!$C$7:$V$95,20,0) -> 0 | M15: =(I15+J15)-L15 -> 35723.6 | Q15: =+L15/R$7 -> 0
A16: PEREZ GORDILLO JEFERSSON ALEXANDER | B16: =+IFERROR(VLOOKUP($A16,'[1]CALCULO BS'!$B$6:$AV$1171,2,0)," ") -> 28427378 | C16: =+IFERROR(VLOOKUP($A16,'[1]CALCULO BS'!$B$6:$AV$1171,3,0)," ") -> 45708 | D16: =+IFERROR(VLOOKUP($A16,'[1]CALCULO BS'!$B$6:$AV$1171,4,0)," ") -> SUPERVISOR DE ALMACEN | E16: =+IFERROR(VLOOKUP($A16,'[1]CALCULO BS'!$B$6:$AV$1171,8,0)," ") -> BANCO VENEZUELA | F16: =+IFERROR(VLOOKUP($A16,'[1]CALCULO BS'!$B$6:$AV$1171,9,0)," ") -> 0102-0741-0200-0059-4888 | G16: =+IFERROR(VLOOKUP($A16,'[1]CALCULO BS'!$B$6:$AV$1171,10,0)," ") -> CORRIENTE | H16: =+IFERROR(VLOOKUP($A16,'[1]CALCULO BS'!$B$6:$AV$1171,5,0)," ") -> FARMACIA LOS YANEZ DE OSPINO, C.A | I16: =VLOOKUP(B16,LISTADOS!$C$7:Q$19,15,0) -> 40944.2 | J16: =(VLOOKUP(B16,'[1]CALCULO BS'!$C$7:$U$95,19,0)*($R$1*[1]LISTADOS!$P$5))-VLOOKUP(B16,'[1]CALCULO BS'!$C$7:$V$95,20,0) -> 0 | M16: =(I16+J16)-L16 -> 40944.2 | Q16: =+L16/R$7 -> 0
A17: LEONARDO ENRRIQUE YANEZ FERRER | B17: =+IFERROR(VLOOKUP($A17,'[1]CALCULO BS'!$B$6:$AV$1171,2,0)," ") -> 29632132 | C17: =+IFERROR(VLOOKUP($A17,'[1]CALCULO BS'!$B$6:$AV$1171,3,0)," ") -> 45712 | D17: =+IFERROR(VLOOKUP($A17,'[1]CALCULO BS'!$B$6:$AV$1171,4,0)," ") -> CAJERO (A) | E17: =+IFERROR(VLOOKUP($A17,'[1]CALCULO BS'!$B$6:$AV$1171,8,0)," ") -> BANCO PROVINCIAL | F17: =+IFERROR(VLOOKUP($A17,'[1]CALCULO BS'!$B$6:$AV$1171,9,0)," ") -> 0108-0064-18-0100331070 | G17: =+IFERROR(VLOOKUP($A17,'[1]CALCULO BS'!$B$6:$AV$1171,10,0)," ") -> CORRIENTE | H17: =+IFERROR(VLOOKUP($A17,'[1]CALCULO BS'!$B$6:$AV$1171,5,0)," ") -> FARMACIA LOS YANEZ DE OSPINO, C.A | I17: =VLOOKUP(B17,LISTADOS!$C$7:Q$19,15,0) -> 42144.2 | J17: =(VLOOKUP(B17,'[1]CALCULO BS'!$C$7:$U$95,19,0)*($R$1*[1]LISTADOS!$P$5))-VLOOKUP(B17,'[1]CALCULO BS'!$C$7:$V$95,20,0) -> 0 | M17: =(I17+J17)-L17 -> 42144.2 | Q17: =+L17/R$7 -> 0
A18: MOISES SEBASTIAN YANEZ FERRER | B18: =+IFERROR(VLOOKUP($A18,'[1]CALCULO BS'!$B$6:$AV$1171,2,0)," ") -> 26940897 | C18: =+IFERROR(VLOOKUP($A18,'[1]CALCULO BS'!$B$6:$AV$1171,3,0)," ") -> 45712 | D18: =+IFERROR(VLOOKUP($A18,'[1]CALCULO BS'!$B$6:$AV$1171,4,0)," ") -> GERENTE | E18: =+IFERROR(VLOOKUP($A18,'[1]CALCULO BS'!$B$6:$AV$1171,8,0)," ") -> BANCO PROVINCIAL | F18: =+IFERROR(VLOOKUP($A18,'[1]CALCULO BS'!$B$6:$AV$1171,9,0)," ") -> 0108-0064-1401-0032-9645 | G18: =+IFERROR(VLOOKUP($A18,'[1]CALCULO BS'!$B$6:$AV$1171,10,0)," ") -> CORRIENTE | H18: =+IFERROR(VLOOKUP($A18,'[1]CALCULO BS'!$B$6:$AV$1171,5,0)," ") -> FARMACIA LOS YANEZ DE OSPINO, C.A | I18: =VLOOKUP(B18,LISTADOS!$C$7:Q$19,15,0) -> 65626.6 | J18: =(VLOOKUP(B18,'[1]CALCULO BS'!$C$7:$U$95,19,0)*($R$1*[1]LISTADOS!$P$5))-VLOOKUP(B18,'[1]CALCULO BS'!$C$7:$V$95,20,0) -> 0 | M18: =(I18+J18)-L18 -> 65626.6 | Q18: =+L18/R$7 -> 0
A19: YENNIFER ALEXANDRA ESPINOZA BOLIVAR | B19: 30240358 | C19: 45999 | D19: PROMOTOR DE VENTA | H19: =+IFERROR(VLOOKUP($A19,'[1]CALCULO BS'!$B$6:$AV$1171,5,0)," ") -> FARMACIA LOS YANEZ DE OSPINO, C.A | I19: =VLOOKUP(B19,LISTADOS!$C$7:Q$19,15,0) -> 22882.4 | J19: 0 | M19: =(I19+J19)-L19 -> 22882.4 | Q19: =+L19/R$7 -> 0
I20: =SUM(I8:I19) -> 479668.6

Sheet RC PAGO BS LOS YANEZ
A1: =+D4 -> FARMACIA LOS YANEZ DE OSPINO, C.A
A3: RECIBO DE PAGO NOMINA
C4: RAZON SOCIAL | D4: FARMACIA LOS YANEZ DE OSPINO, C.A
C5: RIF: | D5: =+VLOOKUP($D$4,[1]DATOS!$C$1:$E$9,2,0) -> J-500253052
C6: DIRECCION: | D6: =+VLOOKUP($D$4,[1]DATOS!$C$1:$E$9,3,0) -> CARRERA 3 ESQUINA CALLE 10, BARRIO CURAZAO- MUNICIPIO GUANARE -PORTUGUESA
C7: PERIODO: | D7: =+[1]LISTADOS!$A$4 -> SEMANA DEL 08/12/2025 AL 14/12/2025
C8: SALARIO MENSUAL: | D8: =VLOOKUP(A10,LISTADOS!$B$7:Q$19,13,0) -> 10000
A9: NOMBRE DEL TRABAJADOR: | C9: CEDULA: | E9: F.INGRESO | G9: CARGO:
A10: YEREHIMA CARDENAS JAIME | C10: =+VLOOKUP(A10,'[1]CALCULO BS'!$B$6:$AW$1286,2,0) -> 15906403 | E10: =+VLOOKUP(A10,'[1]CALCULO BS'!$B$6:$AW$1286,3,0) -> 45362 | G10: =+VLOOKUP(A10,'[1]CALCULO BS'!$B$6:$AW$1286,4,0) -> COORD. ADMINISTRATIVO
A12: CONCEPTO | D12: N° | E12: ASIGNACION | G12: DEDUCCION
A13: Dias laborados | D13: =+VLOOKUP(A10,'CALCULO BS'!$B$6:$AW$1286,16,0) -> 11 | E13: =+VLOOKUP(A10,'CALCULO BS'!$B$6:$AW$1286,17,0) -> 3666.6667
A14: Dias de descanso | D14: =+VLOOKUP(A10,'CALCULO BS'!$B$6:$AW$1286,18,0) -> 4 | E14: =+VLOOKUP(A10,'CALCULO BS'!$B$6:$AW$1286,19,0) -> 1333.3333
A15: Dias de descanso / feriado laborado | D15: =+VLOOKUP(A10,'[1]CALCULO BS'!$B$6:$AW$1286,20,0) -> 0 | E15: =+VLOOKUP(A10,'[1]CALCULO BS'!$B$6:$AW$1286,21,0) -> 0
A16: Reposo 100% | D16: =+VLOOKUP(A10,'[1]CALCULO BS'!$B$6:$AW$1286,22,0) -> 0 | E16: =+VLOOKUP(A10,'CALCULO BS'!$B$6:$AW$1203,23,0) -> 0
A17: Horas extras Diurnas | D17: =+VLOOKUP(A10,'[1]CALCULO BS'!$B$6:$AW$1286,25,0) -> 0 | E17: =+VLOOKUP(A10,'[1]CALCULO BS'!$B$6:$AW$1286,26,0) -> 0
A18: Horas extras nocturno | D18: =+VLOOKUP(A10,'[1]CALCULO BS'!$B$6:$AW$1286,27,0) -> 0 | E18: =+VLOOKUP(A10,'[1]CALCULO BS'!$B$6:$AW$1286,28,0) -> 0
A19: Deduccion IVSS | D19: =+IF(VLOOKUP(A10,'[1]CALCULO BS'!$B$6:$AW$1286,32,0)>1,"1","0") -> 0 | G19: =VLOOKUP(C$10,'[1]CALCULO BS'!C$7:AW$95,34,0) -> 6
A20: Deduccion RPE | D20: =+IF(VLOOKUP(A10,'[1]CALCULO BS'!$B$6:$AW$1286,32,0)>1,"1","0") -> 0 | G20: =VLOOKUP(C10,'[1]CALCULO BS'!C$7:AW$95,35,0) -> 0.75
A21: Deduccion FAOV | D21: 0 | G21: =VLOOKUP(C10,'[1]CALCULO BS'!C$7:AW$95,37,0) -> 25
A22: Permiso no remunerado | D22: =+'CALCULO BS'!AN7 -> 1 | G22: =VLOOKUP(C10,'CALCULO BS'!C$7:AW$14,39,0) -> 333.33333
A23: Falta Injustificada | D23: =+VLOOKUP(A10,'[1]CALCULO BS'!$B$6:$AW$1286,37,0) -> 0 | G23: 0
A24: Prestamo Empleados | D24: 0 | G24: 0
E25: =SUM(E13:F24) -> 5000 | G25: =SUM(G13:G24) -> 365.08333
E26: NETO A PAGAR ==> | G26: =+E25-G25 -> 4634.9167
F28: Firma del Trabajador
A30: RECIBO DE PAGO NOMINA
C31: RAZON SOCIAL | D31: FARMACIA LOS YANEZ DE OSPINO, C.A
C32: RIF: | D32: =+VLOOKUP($D$4,[1]DATOS!$C$1:$E$9,2,0) -> J-500253052
C33: DIRECCION: | D33: =+VLOOKUP($D$4,[1]DATOS!$C$1:$E$9,3,0) -> CARRERA 3 ESQUINA CALLE 10, BARRIO CURAZAO- MUNICIPIO GUANARE -PORTUGUESA
C34: PERIODO: | D34: =+[1]LISTADOS!$A$4 -> SEMANA DEL 08/12/2025 AL 14/12/2025
C35: SALARIO MENSUAL: | D35: =VLOOKUP(A37,LISTADOS!$B$7:Q$19,13,0) -> 5600
A36: NOMBRE DEL TRABAJADOR: | C36: CEDULA: | E36: F.INGRESO | G36: CARGO:
A37: ADRIANA MORENO MARQUEZ | C37: =+VLOOKUP(A37,'[1]CALCULO BS'!$B$6:$AW$1286,2,0) -> 30329814 | E37: =+VLOOKUP(A37,'[1]CALCULO BS'!$B$6:$AW$1286,3,0) -> 45136 | G37: =+VLOOKUP(A37,'[1]CALCULO BS'!$B$6:$AW$1286,4,0) -> CAJERO (A)
A39: CONCEPTO | D39: N° | E39: ASIGNACION | G39: DEDUCCION
A40: Dias laborados | D40: =+VLOOKUP(A37,'CALCULO BS'!$B$6:$AW$1286,16,0) -> 10 | E40: =+VLOOKUP(A37,'CALCULO BS'!$B$6:$AW$1286,17,0) -> 1866.6667
A41: Dias de descanso | D41: =+VLOOKUP(A37,'CALCULO BS'!$B$6:$AW$1286,18,0) -> 4 | E41: =+VLOOKUP(A37,'CALCULO BS'!$B$6:$AW$1286,19,0) -> 872.92121
A42: Dias de descanso / feriado laborado | D42: =+VLOOKUP(A37,'[1]CALCULO BS'!$B$6:$AW$1286,20,0) -> 0 | E42: =+VLOOKUP(A37,'[1]CALCULO BS'!$B$6:$AW$1286,21,0) -> 0
A43: Reposo 100% | D43: =+VLOOKUP(A37,'[1]CALCULO BS'!$B$6:$AW$1286,22,0) -> 1 | E43: =+VLOOKUP(A37,'CALCULO BS'!$B$6:$AW$1286,23,0) -> 186.66667
A44: Horas extras Diurnas | D44: =+VLOOKUP(A37,'[1]CALCULO BS'!$B$6:$AW$1286,25,0) -> 0 | E44: =+VLOOKUP(A37,'[1]CALCULO BS'!$B$6:$AW$1286,26,0) -> 0
A45: Bonos nocturnos | D45: =VLOOKUP(A37,'CALCULO BS'!$B$7:AJ$14,29,0) -> 9 | E45: =VLOOKUP(A37,'CALCULO BS'!$B$7:AO$14,30,0) -> 67.2
...
